Traceback (most recent call last):
  File "D:\PY\Autotestplat\venv\lib\site-packages\requests\packages\urllib3\connection.py", line 141, in _new_conn
    (self.host, self.port), self.timeout, **extra_kw)
  File "D:\PY\Autotestplat\venv\lib\site-packages\requests\packages\urllib3\util\connection.py", line 83, in create_connection
    raise err
  File "D:\PY\Autotestplat\venv\lib\site-packages\requests\packages\urllib3\util\connection.py", line 73, in create_connection
    sock.connect(sa)
ConnectionRefusedError: [WinError 10061] 由于目标计算机积极拒绝，无法连接。

During handling of the above exception, another exception occurred:

Traceback (most recent call last):
  File "D:\PY\Autotestplat\venv\lib\site-packages\requests\packages\urllib3\connectionpool.py", line 600, in urlopen
    chunked=chunked)
  File "D:\PY\Autotestplat\venv\lib\site-packages\requests\packages\urllib3\connectionpool.py", line 356, in _make_request
    conn.request(method, url, **httplib_request_kw)
  File "D:\py\Python\Python36\lib\http\client.py", line 1239, in request
    self._send_request(method, url, body, headers, encode_chunked)
  File "D:\py\Python\Python36\lib\http\client.py", line 1285, in _send_request
    self.endheaders(body, encode_chunked=encode_chunked)
  File "D:\py\Python\Python36\lib\http\client.py", line 1234, in endheaders
    self._send_output(message_body, encode_chunked=encode_chunked)
  File "D:\py\Python\Python36\lib\http\client.py", line 1026, in _send_output
    self.send(msg)
  File "D:\py\Python\Python36\lib\http\client.py", line 964, in send
    self.connect()
  File "D:\PY\Autotestplat\venv\lib\site-packages\requests\packages\urllib3\connection.py", line 166, in connect
    conn = self._new_conn()
  File "D:\PY\Autotestplat\venv\lib\site-packages\requests\packages\urllib3\connection.py", line 150, in _new_conn
    self, "Failed to establish a new connection: %s" % e)
requests.packages.urllib3.exceptions.NewConnectionError: <requests.packages.urllib3.connection.HTTPConnection object at 0x00000177C9285940>: Failed to establish a new connection: [WinError 10061] 由于目标计算机积极拒绝，无法连接。

During handling of the above exception, another exception occurred:

Traceback (most recent call last):
  File "D:\PY\Autotestplat\venv\lib\site-packages\requests\adapters.py", line 439, in send
    timeout=timeout
  File "D:\PY\Autotestplat\venv\lib\site-packages\requests\packages\urllib3\connectionpool.py", line 649, in urlopen
    _stacktrace=sys.exc_info()[2])
  File "D:\PY\Autotestplat\venv\lib\site-packages\requests\packages\urllib3\util\retry.py", line 388, in increment
    raise MaxRetryError(_pool, url, error or ResponseError(cause))
requests.packages.urllib3.exceptions.MaxRetryError: HTTPConnectionPool(host='127.0.0.1', port=80): Max retries exceeded with url: /autotest/user/getTableData/111/222/333/444?id=1123456789011&username=212301989832 (Caused by NewConnectionError('<requests.packages.urllib3.connection.HTTPConnection object at 0x00000177C9285940>: Failed to establish a new connection: [WinError 10061] 由于目标计算机积极拒绝，无法连接。',))

During handling of the above exception, another exception occurred:

Traceback (most recent call last):
  File "D:\PY\Autotestplat\autotest\views_interface.py", line 751, in interface_test_start
    response,cookie = Method_GET(url,body,head,body_format,is_out)
  File "D:\PY\Autotestplat\autotest\views_interface.py", line 837, in Method_GET
    r = request_get(url, body, head, body_format)
  File "D:\PY\Autotestplat\autotest\views_interface.py", line 784, in request_get
    r = session.get(url,params = body, headers=head)
  File "D:\PY\Autotestplat\venv\lib\site-packages\requests\sessions.py", line 535, in get
    return self.request('GET', url, **kwargs)
  File "D:\PY\Autotestplat\venv\lib\site-packages\requests\sessions.py", line 522, in request
    resp = self.send(prep, **send_kwargs)
  File "D:\PY\Autotestplat\venv\lib\site-packages\requests\sessions.py", line 642, in send
    r = adapter.send(request, **kwargs)
  File "D:\PY\Autotestplat\venv\lib\site-packages\requests\adapters.py", line 503, in send
    raise ConnectionError(e, request=request)
requests.exceptions.ConnectionError: HTTPConnectionPool(host='127.0.0.1', port=80): Max retries exceeded with url: /autotest/user/getTableData/111/222/333/444?id=1123456789011&username=212301989832 (Caused by NewConnectionError('<requests.packages.urllib3.connection.HTTPConnection object at 0x00000177C9285940>: Failed to establish a new connection: [WinError 10061] 由于目标计算机积极拒绝，无法连接。',))

